<robot name="DeltaQuad_1">
  <link name="RoBoard_servo-3">
    <inertial>
      <origin xyz="-0.0752751 -0.0509917 -0.0761301" rpy="0 0 0"/>
      <mass value="0.0326959"/>
      <inertia ixx="8.9469e-06" ixy="0.0" ixz="0.0" iyy="5.49064e-06" iyz="-5.81278e-08" izz="5.62832e-06"/>
    </inertial>
    <visual>
      <origin xyz="-0.0652001 -0.0713178 -0.0560379" rpy="0 0 0"/>
      <geometry>
        <mesh filename="C:\Users\stevy\OneDrive\Documents\Steven's Stuff\RIT 5\Robotics Research\VREP\solidowrks_vrep_import\deltaquad_1 - roboard_servo-3.stl"/>
      </geometry>
      <material name="RoBoard_servo-3_color">
        <color rgba="0.792157 0.819608 0.933333 1.0"/>
      </material>
    </visual>
    <collision>
      <origin xyz="-0.0652001 -0.0713178 -0.0560379" rpy="0 0 0"/>
      <geometry>
        <mesh filename="C:\Users\stevy\OneDrive\Documents\Steven's Stuff\RIT 5\Robotics Research\VREP\solidowrks_vrep_import\deltaquad_1 - roboard_servo-3.stl"/>
      </geometry>
    </collision>
  </link>
  <link name="RoBoard_base_1-1">
    <inertial>
      <origin xyz="-0.0196481 0.0094699 0.0219991" rpy="0 0 0"/>
      <mass value="0.0752694"/>
      <inertia ixx="5.11267e-05" ixy="-6.73759e-10" ixz="1.85052e-09" iyy="9.11146e-05" iyz="3.35691e-10" izz="5.11294e-05"/>
    </inertial>
    <visual>
      <origin xyz="0 0 0" rpy="0 0 0"/>
      <geometry>
        <mesh filename="C:\Users\stevy\OneDrive\Documents\Steven's Stuff\RIT 5\Robotics Research\VREP\solidowrks_vrep_import\deltaquad_1 - roboard_base_1-1.stl"/>
      </geometry>
      <material name="RoBoard_base_1-1_color">
        <color rgba="0.792157 0.819608 0.933333 1.0"/>
      </material>
    </visual>
    <collision>
      <origin xyz="0 0 0" rpy="0 0 0"/>
      <geometry>
        <mesh filename="C:\Users\stevy\OneDrive\Documents\Steven's Stuff\RIT 5\Robotics Research\VREP\solidowrks_vrep_import\deltaquad_1 - roboard_base_1-1.stl"/>
      </geometry>
    </collision>
  </link>
  <joint name="RoBoard_base_1-1--RoBoard_servo-3" type="fixed">
    <origin xyz="-0.0602001 -0.0708178 -0.0964379" rpy="3.14159265359 0 -1.57079632679"/>
    <parent link="RoBoard_servo-3"/>
    <child link="RoBoard_base_1-1"/>
    <dynamics damping="0.1"/>
  </joint>
  <link name="RoBoard_servo-1">
    <inertial>
      <origin xyz="-0.010075 0.0203263120893 -0.0200921830098" rpy="0 0 0"/>
      <mass value="0.0326959"/>
      <inertia ixx="8.9469e-06" ixy="0.0" ixz="0.0" iyy="5.49064e-06" iyz="-5.81278e-08" izz="5.62832e-06"/>
    </inertial>
    <visual>
      <origin xyz="0 0 0" rpy="0 0 0"/>
      <geometry>
        <mesh filename="C:\Users\stevy\OneDrive\Documents\Steven's Stuff\RIT 5\Robotics Research\VREP\solidowrks_vrep_import\deltaquad_1 - roboard_servo-1.stl"/>
      </geometry>
      <material name="RoBoard_servo-1_color">
        <color rgba="0.792157 0.819608 0.933333 1.0"/>
      </material>
    </visual>
    <collision>
      <origin xyz="0 0 0" rpy="0 0 0"/>
      <geometry>
        <mesh filename="C:\Users\stevy\OneDrive\Documents\Steven's Stuff\RIT 5\Robotics Research\VREP\solidowrks_vrep_import\deltaquad_1 - roboard_servo-1.stl"/>
      </geometry>
    </collision>
  </link>
  <joint name="RoBoard_base_1-1--RoBoard_servo-1" type="fixed">
    <origin xyz="-0.083765 0.005 0.0357491" rpy="1.04719714741 0 -1.57079632679"/>
    <parent link="RoBoard_base_1-1"/>
    <child link="RoBoard_servo-1"/>
    <dynamics damping="0.1"/>
  </joint>
  <link name="servo_C_bracket-2">
    <inertial>
      <origin xyz="0.009841849933 -0.0152814127643 0.0211505658109" rpy="0 0 0"/>
      <mass value="0.00355141"/>
      <inertia ixx="2.48402e-06" ixy="0.0" ixz="0.0" iyy="1.51807e-06" iyz="0.0" izz="1.30302e-06"/>
    </inertial>
    <visual>
      <origin xyz="0.0218418418103 -0.0347709009925 0.0423007335343" rpy="0 0 0"/>
      <geometry>
        <mesh filename="C:\Users\stevy\OneDrive\Documents\Steven's Stuff\RIT 5\Robotics Research\VREP\solidowrks_vrep_import\deltaquad_1 - servo_c_bracket-2.stl"/>
      </geometry>
      <material name="servo_C_bracket-2_color">
        <color rgba="0.792157 0.819608 0.933333 1.0"/>
      </material>
    </visual>
    <collision>
      <origin xyz="0.0218418418103 -0.0347709009925 0.0423007335343" rpy="0 0 0"/>
      <geometry>
        <mesh filename="C:\Users\stevy\OneDrive\Documents\Steven's Stuff\RIT 5\Robotics Research\VREP\solidowrks_vrep_import\deltaquad_1 - servo_c_bracket-2.stl"/>
      </geometry>
    </collision>
  </link>
  <joint name="RoBoard_servo-1--servo_C_bracket-2" type="continuous">
    <origin xyz="-0.02015 0 0" rpy="-1.57079598047 -0.023045561341 0"/>
    <axis xyz="5.09540848369e-08 -1.43204836933e-07 -0.999999650312"/>
    <parent link="RoBoard_servo-1"/>
    <child link="servo_C_bracket-2"/>
    <dynamics damping="0.1"/>
  </joint>
  <link name="deltaleg_armlink_1-4">
    <inertial>
      <origin xyz="1.12145297645e-07 -0.0265626458706 2.06337951225e-07" rpy="0 0 0"/>
      <mass value="0.00097177"/>
      <inertia ixx="2.29964e-07" ixy="0.0" ixz="0.0" iyy="2.8291e-09" iyz="0.0" izz="2.29964e-07"/>
    </inertial>
    <visual>
      <origin xyz="2.24290595322e-07 -0.0531252917411 4.12675902478e-07" rpy="0 0 0"/>
      <geometry>
        <mesh filename="C:\Users\stevy\OneDrive\Documents\Steven's Stuff\RIT 5\Robotics Research\VREP\solidowrks_vrep_import\deltaquad_1 - deltaleg_armlink_1-4.stl"/>
      </geometry>
      <material name="deltaleg_armlink_1-4_color">
        <color rgba="0.792157 0.819608 0.933333 1.0"/>
      </material>
    </visual>
    <collision>
      <origin xyz="2.24290595322e-07 -0.0531252917411 4.12675902478e-07" rpy="0 0 0"/>
      <geometry>
        <mesh filename="C:\Users\stevy\OneDrive\Documents\Steven's Stuff\RIT 5\Robotics Research\VREP\solidowrks_vrep_import\deltaquad_1 - deltaleg_armlink_1-4.stl"/>
      </geometry>
    </collision>
  </link>
  <joint name="servo_C_bracket-2--deltaleg_armlink_1-4" type="continuous">
    <origin xyz="0.0098418072414 -0.0337706579942 0.0211503715086" rpy="0 -0.523598842892 0"/>
    <axis xyz="-3.47205582674e-07 -0.999999508216 2.00459246091e-07"/>
    <parent link="servo_C_bracket-2"/>
    <child link="deltaleg_armlink_1-4"/>
    <dynamics damping="0.1"/>
  </joint>
  <link name="deltaleg_hinge_link_2-1">
    <inertial>
      <origin xyz="-0.00726776249654 0.00634995458465 -0.00952512770711" rpy="0 0 0"/>
      <mass value="0.00187867"/>
      <inertia ixx="1.24953e-07" ixy="0.0" ixz="0.0" iyy="1.60017e-07" iyz="0.0" izz="8.96468e-08"/>
    </inertial>
    <visual>
      <origin xyz="0 0 0" rpy="0 0 0"/>
      <geometry>
        <mesh filename="C:\Users\stevy\OneDrive\Documents\Steven's Stuff\RIT 5\Robotics Research\VREP\solidowrks_vrep_import\deltaquad_1 - deltaleg_hinge_link_2-1.stl"/>
      </geometry>
      <material name="deltaleg_hinge_link_2-1_color">
        <color rgba="0.792157 0.819608 0.933333 1.0"/>
      </material>
    </visual>
    <collision>
      <origin xyz="0 0 0" rpy="0 0 0"/>
      <geometry>
        <mesh filename="C:\Users\stevy\OneDrive\Documents\Steven's Stuff\RIT 5\Robotics Research\VREP\solidowrks_vrep_import\deltaquad_1 - deltaleg_hinge_link_2-1.stl"/>
      </geometry>
    </collision>
  </link>
  <joint name="deltaleg_armlink_1-4--deltaleg_hinge_link_2-1" type="fixed">
    <origin xyz="-0.0108587461039 -0.0499497858345 -0.003625094887" rpy="-2.48098534517 2.20201681056e-07 1.57079584155"/>
    <parent link="deltaleg_armlink_1-4"/>
    <child link="deltaleg_hinge_link_2-1"/>
    <dynamics damping="0.1"/>
  </joint>
  <link name="deltaleg_knee_joint_1-3">
    <inertial>
      <origin xyz="0.0165166960579 -0.00634953222029 0.0107038472282" rpy="0 0 0"/>
      <mass value="0.00491641"/>
      <inertia ixx="2.27751e-07" ixy="0.0" ixz="-2.01487e-07" iyy="6.86084e-07" iyz="0.0" izz="5.99086e-07"/>
    </inertial>
    <visual>
      <origin xyz="0.0341417458925 -0.0126998633689 0.0204917482151" rpy="0 0 0"/>
      <geometry>
        <mesh filename="C:\Users\stevy\OneDrive\Documents\Steven's Stuff\RIT 5\Robotics Research\VREP\solidowrks_vrep_import\deltaquad_1 - deltaleg_knee_joint_1-3.stl"/>
      </geometry>
      <material name="deltaleg_knee_joint_1-3_color">
        <color rgba="0.792157 0.819608 0.933333 1.0"/>
      </material>
    </visual>
    <collision>
      <origin xyz="0.0341417458925 -0.0126998633689 0.0204917482151" rpy="0 0 0"/>
      <geometry>
        <mesh filename="C:\Users\stevy\OneDrive\Documents\Steven's Stuff\RIT 5\Robotics Research\VREP\solidowrks_vrep_import\deltaquad_1 - deltaleg_knee_joint_1-3.stl"/>
      </geometry>
    </collision>
  </link>
  <joint name="deltaleg_hinge_link_2-1--deltaleg_knee_joint_1-3" type="continuous">
    <origin xyz="-0.0150503485171 0.00634987776503 -0.00317565478195" rpy="1.57079632494 5.20867212084e-07 -0.978061848558"/>
    <axis xyz="5.59857982169e-07 -1.00000046656 6.4957116408e-08"/>
    <parent link="deltaleg_hinge_link_2-1"/>
    <child link="deltaleg_knee_joint_1-3"/>
    <dynamics damping="0.1"/>
  </joint>
  <link name="deltaleg_leg_1-1">
    <inertial>
      <origin xyz="4.74397047059e-07 -0.0905629633169 -2.13233285223e-07" rpy="0 0 0"/>
      <mass value="0.00331316"/>
      <inertia ixx="9.06253e-06" ixy="0.0" ixz="0.0" iyy="9.64556e-09" iyz="0.0" izz="9.06253e-06"/>
    </inertial>
    <visual>
      <origin xyz="0 -0.181124927478 0" rpy="0 0 0"/>
      <geometry>
        <mesh filename="C:\Users\stevy\OneDrive\Documents\Steven's Stuff\RIT 5\Robotics Research\VREP\solidowrks_vrep_import\deltaquad_1 - deltaleg_leg_1-1.stl"/>
      </geometry>
      <material name="deltaleg_leg_1-1_color">
        <color rgba="0.792157 0.819608 0.933333 1.0"/>
      </material>
    </visual>
    <collision>
      <origin xyz="0 -0.181124927478 0" rpy="0 0 0"/>
      <geometry>
        <mesh filename="C:\Users\stevy\OneDrive\Documents\Steven's Stuff\RIT 5\Robotics Research\VREP\solidowrks_vrep_import\deltaquad_1 - deltaleg_leg_1-1.stl"/>
      </geometry>
    </collision>
  </link>
  <joint name="deltaleg_knee_joint_1-3--deltaleg_leg_1-1" type="continuous">
    <origin xyz="0.0141420691598 -0.00635019720209 0.0141422310961" rpy="1.16184360498e-07 -0.514488197518 1.57079641286"/>
    <axis xyz="-3.9238699065e-07 -0.999999808457 -2.18729665796e-07"/>
    <parent link="deltaleg_knee_joint_1-3"/>
    <child link="deltaleg_leg_1-1"/>
    <dynamics damping="0.1"/>
  </joint>
  <link name="deltaleg_platform_link_1-3">
    <inertial>
      <origin xyz="0.00396276833669 0 -4.15740122134e-07" rpy="0 0 0"/>
      <mass value="0.00664445"/>
      <inertia ixx="3.53076e-07" ixy="0.0" ixz="0.0" iyy="1.01049e-06" iyz="0.0" izz="8.4694e-07"/>
    </inertial>
    <visual>
      <origin xyz="1.65312811135e-07 -0.0063498570211 0.0095250111304" rpy="0 0 0"/>
      <geometry>
        <mesh filename="C:\Users\stevy\OneDrive\Documents\Steven's Stuff\RIT 5\Robotics Research\VREP\solidowrks_vrep_import\deltaquad_1 - deltaleg_platform_link_1-3.stl"/>
      </geometry>
      <material name="deltaleg_platform_link_1-3_color">
        <color rgba="0.792157 0.819608 0.933333 1.0"/>
      </material>
    </visual>
    <collision>
      <origin xyz="1.65312811135e-07 -0.0063498570211 0.0095250111304" rpy="0 0 0"/>
      <geometry>
        <mesh filename="C:\Users\stevy\OneDrive\Documents\Steven's Stuff\RIT 5\Robotics Research\VREP\solidowrks_vrep_import\deltaquad_1 - deltaleg_platform_link_1-3.stl"/>
      </geometry>
    </collision>
  </link>
  <joint name="deltaleg_leg_1-1--deltaleg_platform_link_1-3" type="continuous">
    <origin xyz="0 -0.181124927478 0" rpy="-1.07644414956 -2.56562592837e-07 1.57079597384"/>
    <axis xyz="0.999999808457 1.45937516099e-08 -5.26625358044e-08"/>
    <parent link="deltaleg_leg_1-1"/>
    <child link="deltaleg_platform_link_1-3"/>
    <dynamics damping="0.1"/>
  </joint>
  <link name="RoBoard_servo-2">
    <inertial>
      <origin xyz="-0.010075 0.0203260782763 -0.0200921938622" rpy="0 0 0"/>
      <mass value="0.0326959"/>
      <inertia ixx="8.9469e-06" ixy="0.0" ixz="0.0" iyy="5.49064e-06" iyz="-5.81278e-08" izz="5.62832e-06"/>
    </inertial>
    <visual>
      <origin xyz="0 0 0" rpy="0 0 0"/>
      <geometry>
        <mesh filename="C:\Users\stevy\OneDrive\Documents\Steven's Stuff\RIT 5\Robotics Research\VREP\solidowrks_vrep_import\deltaquad_1 - roboard_servo-2.stl"/>
      </geometry>
      <material name="RoBoard_servo-2_color">
        <color rgba="0.792157 0.819608 0.933333 1.0"/>
      </material>
    </visual>
    <collision>
      <origin xyz="0 0 0" rpy="0 0 0"/>
      <geometry>
        <mesh filename="C:\Users\stevy\OneDrive\Documents\Steven's Stuff\RIT 5\Robotics Research\VREP\solidowrks_vrep_import\deltaquad_1 - roboard_servo-2.stl"/>
      </geometry>
    </collision>
  </link>
  <joint name="RoBoard_base_1-1--RoBoard_servo-2" type="fixed">
    <origin xyz="0.024315 0.005 0.0706501" rpy="-1.04719714741 0 -1.57079632679"/>
    <parent link="RoBoard_base_1-1"/>
    <child link="RoBoard_servo-2"/>
    <dynamics damping="0.1"/>
  </joint>
  <link name="servo_C_bracket-4">
    <inertial>
      <origin xyz="-0.00949516612807 -0.0149584810148 -0.0211495197738" rpy="0 0 0"/>
      <mass value="0.00355141"/>
      <inertia ixx="2.48402e-06" ixy="0.0" ixz="0.0" iyy="1.51807e-06" iyz="0.0" izz="1.30302e-06"/>
    </inertial>
    <visual>
      <origin xyz="0.00250488439788 -0.0344481059276 0" rpy="0 0 0"/>
      <geometry>
        <mesh filename="C:\Users\stevy\OneDrive\Documents\Steven's Stuff\RIT 5\Robotics Research\VREP\solidowrks_vrep_import\deltaquad_1 - servo_c_bracket-4.stl"/>
      </geometry>
      <material name="servo_C_bracket-4_color">
        <color rgba="0.792157 0.819608 0.933333 1.0"/>
      </material>
    </visual>
    <collision>
      <origin xyz="0.00250488439788 -0.0344481059276 0" rpy="0 0 0"/>
      <geometry>
        <mesh filename="C:\Users\stevy\OneDrive\Documents\Steven's Stuff\RIT 5\Robotics Research\VREP\solidowrks_vrep_import\deltaquad_1 - servo_c_bracket-4.stl"/>
      </geometry>
    </collision>
  </link>
  <joint name="RoBoard_servo-2--servo_C_bracket-4" type="continuous">
    <origin xyz="-0.02015 0 0" rpy="-1.57079615735 0.0564103704632 3.14159250719"/>
    <axis xyz="-1.57549844636e-07 -2.38723574242e-08 0.999999650312"/>
    <parent link="RoBoard_servo-2"/>
    <child link="servo_C_bracket-4"/>
    <dynamics damping="0.1"/>
  </joint>
  <link name="deltaleg_armlink_1-2">
    <inertial>
      <origin xyz="0 -0.0265622569591 0" rpy="0 0 0"/>
      <mass value="0.00097177"/>
      <inertia ixx="2.29964e-07" ixy="0.0" ixz="0.0" iyy="2.8291e-09" iyz="0.0" izz="2.29964e-07"/>
    </inertial>
    <visual>
      <origin xyz="0 -0.0531245139181 0" rpy="0 0 0"/>
      <geometry>
        <mesh filename="C:\Users\stevy\OneDrive\Documents\Steven's Stuff\RIT 5\Robotics Research\VREP\solidowrks_vrep_import\deltaquad_1 - deltaleg_armlink_1-2.stl"/>
      </geometry>
      <material name="deltaleg_armlink_1-2_color">
        <color rgba="0.792157 0.819608 0.933333 1.0"/>
      </material>
    </visual>
    <collision>
      <origin xyz="0 -0.0531245139181 0" rpy="0 0 0"/>
      <geometry>
        <mesh filename="C:\Users\stevy\OneDrive\Documents\Steven's Stuff\RIT 5\Robotics Research\VREP\solidowrks_vrep_import\deltaquad_1 - deltaleg_armlink_1-2.stl"/>
      </geometry>
    </collision>
  </link>
  <joint name="servo_C_bracket-4--deltaleg_armlink_1-2" type="continuous">
    <origin xyz="-0.0094951159743 -0.0334480422653 -0.0211496094652" rpy="0 0.523598830654 0"/>
    <axis xyz="-1.07280164308e-07 -1.00000026708 -6.19382618527e-08"/>
    <parent link="servo_C_bracket-4"/>
    <child link="deltaleg_armlink_1-2"/>
    <dynamics damping="0.1"/>
  </joint>
  <link name="deltaleg_hinge_link_2-3">
    <inertial>
      <origin xyz="-0.00409287092912 0 1.99232277037e-07" rpy="0 0 0"/>
      <mass value="0.00187867"/>
      <inertia ixx="1.24953e-07" ixy="0.0" ixz="0.0" iyy="1.60017e-07" iyz="0.0" izz="8.96468e-08"/>
    </inertial>
    <visual>
      <origin xyz="0.00317409540992 -0.00635010031969 0.00952506658815" rpy="0 0 0"/>
      <geometry>
        <mesh filename="C:\Users\stevy\OneDrive\Documents\Steven's Stuff\RIT 5\Robotics Research\VREP\solidowrks_vrep_import\deltaquad_1 - deltaleg_hinge_link_2-3.stl"/>
      </geometry>
      <material name="deltaleg_hinge_link_2-3_color">
        <color rgba="0.792157 0.819608 0.933333 1.0"/>
      </material>
    </visual>
    <collision>
      <origin xyz="0.00317409540992 -0.00635010031969 0.00952506658815" rpy="0 0 0"/>
      <geometry>
        <mesh filename="C:\Users\stevy\OneDrive\Documents\Steven's Stuff\RIT 5\Robotics Research\VREP\solidowrks_vrep_import\deltaquad_1 - deltaleg_hinge_link_2-3.stl"/>
      </geometry>
    </collision>
  </link>
  <joint name="deltaleg_armlink_1-2--deltaleg_hinge_link_2-3" type="continuous">
    <origin xyz="0 -0.0531245139181 0" rpy="2.46122980591 -2.23017588397e-07 1.57079609749"/>
    <axis xyz="1.00000026708 -1.96189899535e-07 4.84485326857e-08"/>
    <parent link="deltaleg_armlink_1-2"/>
    <child link="deltaleg_hinge_link_2-3"/>
    <dynamics damping="0.1"/>
  </joint>
  <link name="deltaleg_knee_joint_1-1">
    <inertial>
      <origin xyz="0.0165163024647 0.00635055804317 0.01070405099" rpy="0 0 0"/>
      <mass value="0.00491641"/>
      <inertia ixx="2.27751e-07" ixy="0.0" ixz="-2.01487e-07" iyy="6.86084e-07" iyz="0.0" izz="5.99086e-07"/>
    </inertial>
    <visual>
      <origin xyz="0.0341418990737 4.51483605515e-07 0.0204922806489" rpy="0 0 0"/>
      <geometry>
        <mesh filename="C:\Users\stevy\OneDrive\Documents\Steven's Stuff\RIT 5\Robotics Research\VREP\solidowrks_vrep_import\deltaquad_1 - deltaleg_knee_joint_1-1.stl"/>
      </geometry>
      <material name="deltaleg_knee_joint_1-1_color">
        <color rgba="0.792157 0.819608 0.933333 1.0"/>
      </material>
    </visual>
    <collision>
      <origin xyz="0.0341418990737 4.51483605515e-07 0.0204922806489" rpy="0 0 0"/>
      <geometry>
        <mesh filename="C:\Users\stevy\OneDrive\Documents\Steven's Stuff\RIT 5\Robotics Research\VREP\solidowrks_vrep_import\deltaquad_1 - deltaleg_knee_joint_1-1.stl"/>
      </geometry>
    </collision>
  </link>
  <joint name="deltaleg_hinge_link_2-3--deltaleg_knee_joint_1-1" type="continuous">
    <origin xyz="-0.0118754155958 -1.26669973483e-07 0.00635055437741" rpy="-1.57079657383 1.52615157567e-07 0.99156261699"/>
    <axis xyz="3.19482886951e-07 0.99999997682 4.16754610044e-07"/>
    <parent link="deltaleg_hinge_link_2-3"/>
    <child link="deltaleg_knee_joint_1-1"/>
    <dynamics damping="0.1"/>
  </joint>
  <link name="deltaleg_leg_1-2">
    <inertial>
      <origin xyz="-1.72411146693e-07 -0.0905626151616 -2.37496601635e-07" rpy="0 0 0"/>
      <mass value="0.00331316"/>
      <inertia ixx="9.06253e-06" ixy="0.0" ixz="0.0" iyy="9.64556e-09" iyz="0.0" izz="9.06253e-06"/>
    </inertial>
    <visual>
      <origin xyz="-1.14883075053e-07 -0.181125404018 -3.91578237557e-07" rpy="0 0 0"/>
      <geometry>
        <mesh filename="C:\Users\stevy\OneDrive\Documents\Steven's Stuff\RIT 5\Robotics Research\VREP\solidowrks_vrep_import\deltaquad_1 - deltaleg_leg_1-2.stl"/>
      </geometry>
      <material name="deltaleg_leg_1-2_color">
        <color rgba="0.792157 0.819608 0.933333 1.0"/>
      </material>
    </visual>
    <collision>
      <origin xyz="-1.14883075053e-07 -0.181125404018 -3.91578237557e-07" rpy="0 0 0"/>
      <geometry>
        <mesh filename="C:\Users\stevy\OneDrive\Documents\Steven's Stuff\RIT 5\Robotics Research\VREP\solidowrks_vrep_import\deltaquad_1 - deltaleg_leg_1-2.stl"/>
      </geometry>
    </collision>
  </link>
  <joint name="deltaleg_knee_joint_1-1--deltaleg_leg_1-2" type="continuous">
    <origin xyz="0.0141419713027 0.00635057996879 0.0141423756595" rpy="8.99262157587e-07 1.27982745915 1.57079729711"/>
    <axis xyz="-1.57584838026e-08 -1.00000035554 -4.43658857152e-08"/>
    <parent link="deltaleg_knee_joint_1-1"/>
    <child link="deltaleg_leg_1-2"/>
    <dynamics damping="0.1"/>
  </joint>
  <link name="deltaleg_platform_link_1-1">
    <inertial>
      <origin xyz="0.00396344484676 0.00634949835256 -0.00952530670726" rpy="0 0 0"/>
      <mass value="0.00664445"/>
      <inertia ixx="3.53076e-07" ixy="0.0" ixz="0.0" iyy="1.01049e-06" iyz="0.0" izz="8.4694e-07"/>
    </inertial>
    <visual>
      <origin xyz="0 0 0" rpy="0 0 0"/>
      <geometry>
        <mesh filename="C:\Users\stevy\OneDrive\Documents\Steven's Stuff\RIT 5\Robotics Research\VREP\solidowrks_vrep_import\deltaquad_1 - deltaleg_platform_link_1-1.stl"/>
      </geometry>
      <material name="deltaleg_platform_link_1-1_color">
        <color rgba="0.792157 0.819608 0.933333 1.0"/>
      </material>
    </visual>
    <collision>
      <origin xyz="0 0 0" rpy="0 0 0"/>
      <geometry>
        <mesh filename="C:\Users\stevy\OneDrive\Documents\Steven's Stuff\RIT 5\Robotics Research\VREP\solidowrks_vrep_import\deltaquad_1 - deltaleg_platform_link_1-1.stl"/>
      </geometry>
    </collision>
  </link>
  <joint name="deltaleg_leg_1-2--deltaleg_platform_link_1-1" type="fixed">
    <origin xyz="0.0089008416837 -0.181125278746 0.00719870943443" rpy="0.30275357663 -1.62275700072e-07 1.57079601895"/>
    <parent link="deltaleg_leg_1-2"/>
    <child link="deltaleg_platform_link_1-1"/>
    <dynamics damping="0.1"/>
  </joint>
  <link name="servo_C_bracket-3">
    <inertial>
      <origin xyz="-0.00535056767612 -0.0123624120864 -0.02115" rpy="0 0 0"/>
      <mass value="0.00355141"/>
      <inertia ixx="2.48402e-06" ixy="0.0" ixz="0.0" iyy="1.51807e-06" iyz="0.0" izz="1.30302e-06"/>
    </inertial>
    <visual>
      <origin xyz="0.00664921017292 -0.0318517347522 0" rpy="0 0 0"/>
      <geometry>
        <mesh filename="C:\Users\stevy\OneDrive\Documents\Steven's Stuff\RIT 5\Robotics Research\VREP\solidowrks_vrep_import\deltaquad_1 - servo_c_bracket-3.stl"/>
      </geometry>
      <material name="servo_C_bracket-3_color">
        <color rgba="0.792157 0.819608 0.933333 1.0"/>
      </material>
    </visual>
    <collision>
      <origin xyz="0.00664921017292 -0.0318517347522 0" rpy="0 0 0"/>
      <geometry>
        <mesh filename="C:\Users\stevy\OneDrive\Documents\Steven's Stuff\RIT 5\Robotics Research\VREP\solidowrks_vrep_import\deltaquad_1 - servo_c_bracket-3.stl"/>
      </geometry>
    </collision>
  </link>
  <joint name="RoBoard_servo-3--servo_C_bracket-3" type="continuous">
    <origin xyz="-0.0853501 -0.0713178 -0.0560379" rpy="-1.57079632679 0.402653928491 -3.14159265359"/>
    <axis xyz="1.11022302463e-16 0.0 1.0"/>
    <parent link="RoBoard_servo-3"/>
    <child link="servo_C_bracket-3"/>
    <dynamics damping="0.1"/>
  </joint>
  <link name="deltaleg_armlink_1-3">
    <inertial>
      <origin xyz="0 -0.0265625394368 -1.74093815752e-07" rpy="0 0 0"/>
      <mass value="0.00097177"/>
      <inertia ixx="2.29964e-07" ixy="0.0" ixz="0.0" iyy="2.8291e-09" iyz="0.0" izz="2.29964e-07"/>
    </inertial>
    <visual>
      <origin xyz="-1.68086298323e-07 -0.0531251524756 -3.21218102867e-07" rpy="0 0 0"/>
      <geometry>
        <mesh filename="C:\Users\stevy\OneDrive\Documents\Steven's Stuff\RIT 5\Robotics Research\VREP\solidowrks_vrep_import\deltaquad_1 - deltaleg_armlink_1-3.stl"/>
      </geometry>
      <material name="deltaleg_armlink_1-3_color">
        <color rgba="0.792157 0.819608 0.933333 1.0"/>
      </material>
    </visual>
    <collision>
      <origin xyz="-1.68086298323e-07 -0.0531251524756 -3.21218102867e-07" rpy="0 0 0"/>
      <geometry>
        <mesh filename="C:\Users\stevy\OneDrive\Documents\Steven's Stuff\RIT 5\Robotics Research\VREP\solidowrks_vrep_import\deltaquad_1 - deltaleg_armlink_1-3.stl"/>
      </geometry>
    </collision>
  </link>
  <joint name="servo_C_bracket-3--deltaleg_armlink_1-3" type="continuous">
    <origin xyz="-0.00535064456884 -0.0308517830201 -0.02115" rpy="3.14159194663 -1.0358648468 -3.14159265099"/>
    <axis xyz="1.35455061806e-07 -0.999999601948 -4.78364313772e-07"/>
    <parent link="servo_C_bracket-3"/>
    <child link="deltaleg_armlink_1-3"/>
    <dynamics damping="0.1"/>
  </joint>
  <link name="deltaleg_hinge_link_2-2">
    <inertial>
      <origin xyz="-0.00409232117901 6.76610438247e-07 0" rpy="0 0 0"/>
      <mass value="0.00187867"/>
      <inertia ixx="1.24953e-07" ixy="0.0" ixz="0.0" iyy="1.60017e-07" iyz="0.0" izz="8.96468e-08"/>
    </inertial>
    <visual>
      <origin xyz="0.00317510444268 -0.00634975607276 0.00952503747681" rpy="0 0 0"/>
      <geometry>
        <mesh filename="C:\Users\stevy\OneDrive\Documents\Steven's Stuff\RIT 5\Robotics Research\VREP\solidowrks_vrep_import\deltaquad_1 - deltaleg_hinge_link_2-2.stl"/>
      </geometry>
      <material name="deltaleg_hinge_link_2-2_color">
        <color rgba="0.792157 0.819608 0.933333 1.0"/>
      </material>
    </visual>
    <collision>
      <origin xyz="0.00317510444268 -0.00634975607276 0.00952503747681" rpy="0 0 0"/>
      <geometry>
        <mesh filename="C:\Users\stevy\OneDrive\Documents\Steven's Stuff\RIT 5\Robotics Research\VREP\solidowrks_vrep_import\deltaquad_1 - deltaleg_hinge_link_2-2.stl"/>
      </geometry>
    </collision>
  </link>
  <joint name="deltaleg_armlink_1-3--deltaleg_hinge_link_2-2" type="continuous">
    <origin xyz="-1.68086298323e-07 -0.0531251524756 -3.21218102867e-07" rpy="2.11273627754 -9.60329490318e-07 1.57079684801"/>
    <axis xyz="0.999999601948 -2.1392867422e-07 5.79082294001e-07"/>
    <parent link="deltaleg_armlink_1-3"/>
    <child link="deltaleg_hinge_link_2-2"/>
    <dynamics damping="0.1"/>
  </joint>
  <link name="deltaleg_knee_joint_1-2">
    <inertial>
      <origin xyz="0.0165164012971 -0.00635004628256 0.0107039090828" rpy="0 0 0"/>
      <mass value="0.00491641"/>
      <inertia ixx="2.27751e-07" ixy="0.0" ixz="-2.01487e-07" iyy="6.86084e-07" iyz="0.0" izz="5.99086e-07"/>
    </inertial>
    <visual>
      <origin xyz="0.0341424019224 -0.0127000617971 0.0204923896432" rpy="0 0 0"/>
      <geometry>
        <mesh filename="C:\Users\stevy\OneDrive\Documents\Steven's Stuff\RIT 5\Robotics Research\VREP\solidowrks_vrep_import\deltaquad_1 - deltaleg_knee_joint_1-2.stl"/>
      </geometry>
      <material name="deltaleg_knee_joint_1-2_color">
        <color rgba="0.792157 0.819608 0.933333 1.0"/>
      </material>
    </visual>
    <collision>
      <origin xyz="0.0341424019224 -0.0127000617971 0.0204923896432" rpy="0 0 0"/>
      <geometry>
        <mesh filename="C:\Users\stevy\OneDrive\Documents\Steven's Stuff\RIT 5\Robotics Research\VREP\solidowrks_vrep_import\deltaquad_1 - deltaleg_knee_joint_1-2.stl"/>
      </geometry>
    </collision>
  </link>
  <joint name="deltaleg_hinge_link_2-2--deltaleg_knee_joint_1-2" type="continuous">
    <origin xyz="-0.0118748417251 2.55093404414e-07 0.00635004730594" rpy="1.57079672693 0 -1.11193415618"/>
    <axis xyz="4.45860778137e-08 -0.999999560666 -2.14907434564e-07"/>
    <parent link="deltaleg_hinge_link_2-2"/>
    <child link="deltaleg_knee_joint_1-2"/>
    <dynamics damping="0.1"/>
  </joint>
  <link name="deltaleg_leg_1-3">
    <inertial>
      <origin xyz="-1.463774209e-07 -0.0905622030836 2.61040138311e-07" rpy="0 0 0"/>
      <mass value="0.00331316"/>
      <inertia ixx="9.06253e-06" ixy="0.0" ixz="0.0" iyy="9.64556e-09" iyz="0.0" izz="9.06253e-06"/>
    </inertial>
    <visual>
      <origin xyz="-4.57480864656e-07 -0.181124709696 7.23910805078e-07" rpy="0 0 0"/>
      <geometry>
        <mesh filename="C:\Users\stevy\OneDrive\Documents\Steven's Stuff\RIT 5\Robotics Research\VREP\solidowrks_vrep_import\deltaquad_1 - deltaleg_leg_1-3.stl"/>
      </geometry>
      <material name="deltaleg_leg_1-3_color">
        <color rgba="0.792157 0.819608 0.933333 1.0"/>
      </material>
    </visual>
    <collision>
      <origin xyz="-4.57480864656e-07 -0.181124709696 7.23910805078e-07" rpy="0 0 0"/>
      <geometry>
        <mesh filename="C:\Users\stevy\OneDrive\Documents\Steven's Stuff\RIT 5\Robotics Research\VREP\solidowrks_vrep_import\deltaquad_1 - deltaleg_leg_1-3.stl"/>
      </geometry>
    </collision>
  </link>
  <joint name="deltaleg_knee_joint_1-2--deltaleg_leg_1-3" type="continuous">
    <origin xyz="0.0141423470748 -0.00634999083229 0.0141423283195" rpy="-3.14159262424 -0.680300344397 -1.57079620813"/>
    <axis xyz="3.53246020379e-07 -1.00000015969 -3.00610922266e-07"/>
    <parent link="deltaleg_knee_joint_1-2"/>
    <child link="deltaleg_leg_1-3"/>
    <dynamics damping="0.1"/>
  </joint>
  <link name="deltaleg_platform_link_1-2">
    <inertial>
      <origin xyz="0.00413878987538 6.06202289088e-07 0" rpy="0 0 0"/>
      <mass value="0.00664445"/>
      <inertia ixx="3.53076e-07" ixy="0.0" ixz="0.0" iyy="1.01049e-06" iyz="0.0" izz="8.4694e-07"/>
    </inertial>
    <visual>
      <origin xyz="0.000174939065205 -0.00634959533893 0.00952502788265" rpy="0 0 0"/>
      <geometry>
        <mesh filename="C:\Users\stevy\OneDrive\Documents\Steven's Stuff\RIT 5\Robotics Research\VREP\solidowrks_vrep_import\deltaquad_1 - deltaleg_platform_link_1-2.stl"/>
      </geometry>
      <material name="deltaleg_platform_link_1-2_color">
        <color rgba="0.792157 0.819608 0.933333 1.0"/>
      </material>
    </visual>
    <collision>
      <origin xyz="0.000174939065205 -0.00634959533893 0.00952502788265" rpy="0 0 0"/>
      <geometry>
        <mesh filename="C:\Users\stevy\OneDrive\Documents\Steven's Stuff\RIT 5\Robotics Research\VREP\solidowrks_vrep_import\deltaquad_1 - deltaleg_platform_link_1-2.stl"/>
      </geometry>
    </collision>
  </link>
  <joint name="deltaleg_leg_1-3--deltaleg_platform_link_1-2" type="continuous">
    <origin xyz="-4.57480864656e-07 -0.181124709696 7.23910805078e-07" rpy="-2.26202542899 -1.34662557882e-07 1.57079637268"/>
    <axis xyz="1.00000015969 -3.23792525903e-07 1.31017805387e-07"/>
    <parent link="deltaleg_leg_1-3"/>
    <child link="deltaleg_platform_link_1-2"/>
    <dynamics damping="0.1"/>
  </joint>
  <link name="deltaquad_platform_1-1">
    <inertial>
      <origin xyz="-0.0342071021102 -0.0117319096984 0.00634994529907" rpy="0 0 0"/>
      <mass value="0.018221"/>
      <inertia ixx="6.31274e-06" ixy="-9.20115e-12" ixz="-1.53526e-15" iyy="1.19866e-05" iyz="3.50719e-16" izz="6.31273e-06"/>
    </inertial>
    <visual>
      <origin xyz="-0.0342068982163 -0.0159996250022 0.00635000617446" rpy="0 0 0"/>
      <geometry>
        <mesh filename="C:\Users\stevy\OneDrive\Documents\Steven's Stuff\RIT 5\Robotics Research\VREP\solidowrks_vrep_import\deltaquad_1 - deltaquad_platform_1-1.stl"/>
      </geometry>
      <material name="deltaquad_platform_1-1_color">
        <color rgba="0.792157 0.819608 0.933333 1.0"/>
      </material>
    </visual>
    <collision>
      <origin xyz="-0.0342068982163 -0.0159996250022 0.00635000617446" rpy="0 0 0"/>
      <geometry>
        <mesh filename="C:\Users\stevy\OneDrive\Documents\Steven's Stuff\RIT 5\Robotics Research\VREP\solidowrks_vrep_import\deltaquad_1 - deltaquad_platform_1-1.stl"/>
      </geometry>
    </collision>
  </link>
  <joint name="deltaleg_platform_link_1-2--deltaquad_platform_1-1" type="continuous">
    <origin xyz="-0.0148749698602 1.07043315148e-06 0.00635003221668" rpy="3.1415924053 0 0.889797100476"/>
    <axis xyz="-1.45700952658e-07 6.09153637503e-08 1.00000020461"/>
    <parent link="deltaleg_platform_link_1-2"/>
    <child link="deltaquad_platform_1-1"/>
    <dynamics damping="0.1"/>
  </joint>
  <link name="10_24_1_5_screw-1">
    <inertial>
      <origin xyz="-4.17881569285e-07 -0.0148294810827 -4.50257188742e-07" rpy="0 0 0"/>
      <mass value="0.000877038"/>
      <inertia ixx="1.46939e-07" ixy="0.0" ixz="0.0" iyy="4.04014e-09" iyz="0.0" izz="1.46939e-07"/>
    </inertial>
    <visual>
      <origin xyz="0 0 0" rpy="0 0 0"/>
      <geometry>
        <mesh filename="C:\Users\stevy\OneDrive\Documents\Steven's Stuff\RIT 5\Robotics Research\VREP\solidowrks_vrep_import\deltaquad_1 - 10_24_1_5_screw-1.stl"/>
      </geometry>
      <material name="10_24_1_5_screw-1_color">
        <color rgba="0.792157 0.819608 0.933333 1.0"/>
      </material>
    </visual>
    <collision>
      <origin xyz="0 0 0" rpy="0 0 0"/>
      <geometry>
        <mesh filename="C:\Users\stevy\OneDrive\Documents\Steven's Stuff\RIT 5\Robotics Research\VREP\solidowrks_vrep_import\deltaquad_1 - 10_24_1_5_screw-1.stl"/>
      </geometry>
    </collision>
  </link>
  <joint name="10_24_1_5_screw-1--deltaquad_platform_1-1" type="continuous">
    <origin xyz="-0.0342065237066 -0.010999841625 0.00634998262855" rpy="-2.84041753345e-07 0.813199312049 -1.09526298884e-07"/>
    <axis xyz="4.02167644603e-08 -0.999999862932 -1.02381573386e-07"/>
    <parent link="deltaquad_platform_1-1"/>
    <child link="10_24_1_5_screw-1"/>
    <dynamics damping="0.1"/>
  </joint>
  <link name="deltaleg_toe_1-1">
    <inertial>
      <origin xyz="1.37574109958e-07 -0.00287281268965 -7.68951527369e-07" rpy="0 0 0"/>
      <mass value="0.015563"/>
      <inertia ixx="1.58633e-06" ixy="0.0" ixz="0.0" iyy="2.6038e-06" iyz="0.0" izz="1.58633e-06"/>
    </inertial>
    <visual>
      <origin xyz="0 -0.00999938722033 -2.40762617135e-07" rpy="0 0 0"/>
      <geometry>
        <mesh filename="C:\Users\stevy\OneDrive\Documents\Steven's Stuff\RIT 5\Robotics Research\VREP\solidowrks_vrep_import\deltaquad_1 - deltaleg_toe_1-1.stl"/>
      </geometry>
      <material name="deltaleg_toe_1-1_color">
        <color rgba="0.792157 0.819608 0.933333 1.0"/>
      </material>
    </visual>
    <collision>
      <origin xyz="0 -0.00999938722033 -2.40762617135e-07" rpy="0 0 0"/>
      <geometry>
        <mesh filename="C:\Users\stevy\OneDrive\Documents\Steven's Stuff\RIT 5\Robotics Research\VREP\solidowrks_vrep_import\deltaquad_1 - deltaleg_toe_1-1.stl"/>
      </geometry>
    </collision>
  </link>
  <joint name="10_24_1_5_screw-1--deltaleg_toe_1-1" type="continuous">
    <origin xyz="1.27879436797e-07 -0.0380996619371 1.36375745696e-07" rpy="-3.86265859836e-07 -0.593780057733 -3.14159258683"/>
    <axis xyz="-3.52830823447e-08 0.999999862932 2.86558277884e-07"/>
    <parent link="10_24_1_5_screw-1"/>
    <child link="deltaleg_toe_1-1"/>
    <dynamics damping="0.1"/>
  </joint>
</robot>
